Workbook
Name documentLog: database!$Q:$X
Name docNumDescOther: database!$AA$1:$AA$1956
Name customerDetails: database!$AC:$AI
Name Pelanggan_fakturperiode: #REF!
Name itemCategoryDetails: database!$BB:$BG
Name customInv: database!$AL$2:$AQ$2499
Name inventoryLog: database!$A:$O
Name docNumDescNormal: database!$Z$2:$Z$1956
Name concatDocNumber: database!$AL:$AL

Sheet Faktur
F3: Kepada Yth :
F4: {=IFERROR(INDEX(customerDetails,MATCH(C13,INDEX(customerDetails,,1),0),2),"")} -> Bengkel Las Bpk. Ari
F5: {=IFERROR(INDEX(customerDetails,MATCH($C$13,INDEX(customerDetails,,1),0),5),"")} -> Sumber Kembar, Wonodadi, Kec. Kutorejo, Kabupaten Mojokerto, Jawa Timur
A6: Jl. Parengan Kali 19, Parengan, Kraton, Kec. Krian, Kab. Sidoarjo, Jawa Timur Telp : 085655863676 Email : atmakarsa.id@gmail.com
A11: FAKTUR PENJUALAN
A12: NPWP | C12: {=IFERROR(INDEX(customerDetails,MATCH(C13,INDEX(customerDetails,,1),0),3),"")} | E12: No. Faktur | F12: 04261063117
A13: ID Pelanggan | C13: {=INDEX(documentLog,MATCH($F$12,INDEX(documentLog,,2),0),3)} -> b2b5f2c5 | E13: Tgl. Faktur | F13: {=INDEX(documentLog,MATCH($F$12,INDEX(documentLog,,2),0),5)} -> 46129.511
A14: No. PO | E14: Batas Pembayaran | F14: {=F13 + INDEX(customerDetails,MATCH(C13,INDEX(customerDetails,,1),0),6)} -> 46143.511
A16: No | B16: Nama Barang | D16: Satuan | E16: Kuantitas | F16: Harga Satuan | G16: Jumlah
A17: {=IFERROR(SEQUENCE(COUNTA(B17:B21),1),"")} -> 1 | B17: =IFERROR(__xludf.DUMMYFUNCTION("QUERY(inventoryLog,""SELECT G WHERE B='""&F12&""'"",)"),"Oksigen 6m3") -> Oksigen 6m3 | D17: {=IF(ISBLANK($B17),"", INDEX(itemCategoryDetails,MATCH($B17,INDEX(itemCategoryDetails,,2),0),5))} -> Btl | E17: =IFERROR(__xludf.DUMMYFUNCTION("QUERY(inventoryLog,""SELECT J,L WHERE B='""&F12&""'"",)"),2.0) -> 2 | F17: =IFERROR(__xludf.DUMMYFUNCTION("""COMPUTED_VALUE"""),60000.0) -> 60000 | G17: =F17*E17 -> 120000
A18: 2 | B18: =IFERROR(__xludf.DUMMYFUNCTION("""COMPUTED_VALUE"""),"Karbondioksida") -> Karbondioksida | D18: {=IF(ISBLANK($B18),"", INDEX(itemCategoryDetails,MATCH($B18,INDEX(itemCategoryDetails,,2),0),5))} -> Btl | E18: =IFERROR(__xludf.DUMMYFUNCTION("""COMPUTED_VALUE"""),2.0) -> 2 | F18: =IFERROR(__xludf.DUMMYFUNCTION("""COMPUTED_VALUE"""),180000.0) -> 180000 | G18: =F18*E18 -> 360000
D19: {=IF(ISBLANK($B19),"", INDEX(itemCategoryDetails,MATCH($B19,INDEX(itemCategoryDetails,,2),0),5))} | G19: =F19*E19 -> 0
D20: {=IF(ISBLANK($B20),"", INDEX(itemCategoryDetails,MATCH($B20,INDEX(itemCategoryDetails,,2),0),5))} | G20: =F20*E20 -> 0
D21: =IF(B21<>"", "Btl", "")
E22: Harga Jual | G22: =SUM(G17:G21) -> 480000
E23: Ongkos Kirim
E24: Potongan Harga
E25: Uang Muka Diterima
E26: Dasar Pengenaan Pajak | G26: {=IFERROR(IF(INDEX(customerDetails,MATCH(C13,INDEX(customerDetails,,1),0),4)=TRUE,G22,""),"")}
E27: PPN 11% | G27: {=IFERROR(IF(INDEX(customerDetails,MATCH(C13,INDEX(customerDetails,,1),0),4)=TRUE,G22*11/100,""),"")}
E28: Jumlah yang Harus Dibayarkan | G28: =G22+G27+G23 -> 480000
A30: Catatan : | F30: ="Sidoarjo,"&" "&text(F13,"dd mmmm yyy") -> Sidoarjo, 17 April 2026
F35: Wahyono
B46: =IMAGE("https://qris.interactive.co.id/restapi/qris/show_qris.php") | G46: =IMAGE("https://quickchart.io/qr?text=" & ENCODEURL($F$12))
A49: Mohon sertakan nomor faktur pada berita/note. Pembayaran sah apabila terdapat bukti transfer ke :
B51: BRI | C51: 055301001926309 (Atma Karsa Gasindo)
B52: BNI | C52: 1895607235 (Atma Karsa Gasindo)
B53: BCA | C53: 1841622478 (Rizki Kurniawan) | F53: Customer Service : | G53: WA 081333292028

Sheet Surat Jalan
E1: SURAT JALAN
E3: Nomor Dokumen | F3: =Faktur!$F$12 -> 04261063117
E4: Tanggal | F4: {=INDEX(documentLog,MATCH($F$3,INDEX(documentLog,,2),0),5)} -> 46129.511
A5: Jl. Parengan Kali 19, Parengan, Kraton, Kec. Krian, Kab. Sidoarjo, Jawa Timur Telp : 085655863676 Email : atmakarsa.id@gmail.com | E5: No. Polisi | F5: L 8314 JQ
E6: Driver | F6: Sugiyono
E7: Telp. Driver | F7: 085850403150
A10: Alamat : | D10: Kepada Yth :
A11: {=INDEX(documentLog,MATCH($F$3,INDEX(documentLog,,2),0),6)} -> Sumber Kembar, Wonodadi, Kec. Kutorejo, Kabupaten Mojokerto, Jawa Timur | D11: {=INDEX(documentLog,MATCH($F$3,INDEX(documentLog,,2),0),4)} -> Bengkel Las Bpk. Ari
A13: No | B13: Nama Barang | E13: Satuan | F13: Jumlah
A15: {=IFERROR(SEQUENCE(COUNTA(B15:B19),1),"")} -> 1 | B15: =IFERROR(__xludf.DUMMYFUNCTION("QUERY(inventoryLog,""SELECT G,K WHERE B='""&F3&""'"",)"),"Oksigen 6m3") -> Oksigen 6m3 | C15: =IFERROR(__xludf.DUMMYFUNCTION("""COMPUTED_VALUE"""),"11244 11235") -> 11244 11235 | E15: {=IF(ISBLANK($B15),"", INDEX(itemCategoryDetails,MATCH($B15,INDEX(itemCategoryDetails,,2),0),5))} -> Btl | F15: =IFERROR(__xludf.DUMMYFUNCTION("QUERY(inventoryLog,""SELECT J WHERE B='""&F3&""'"",)"),2.0) -> 2
A16: 2 | B16: =IFERROR(__xludf.DUMMYFUNCTION("""COMPUTED_VALUE"""),"Karbondioksida") -> Karbondioksida | C16: =IFERROR(__xludf.DUMMYFUNCTION("""COMPUTED_VALUE"""),"13024 13074") -> 13024 13074 | E16: {=IF(ISBLANK($B16),"", INDEX(itemCategoryDetails,MATCH($B16,INDEX(itemCategoryDetails,,2),0),5))} -> Btl | F16: =IFERROR(__xludf.DUMMYFUNCTION("""COMPUTED_VALUE"""),2.0) -> 2
E17: {=IF(ISBLANK($B17),"", INDEX(itemCategoryDetails,MATCH($B17,INDEX(itemCategoryDetails,,2),0),5))}
E18: {=IF(ISBLANK($B18),"", INDEX(itemCategoryDetails,MATCH($B18,INDEX(itemCategoryDetails,,2),0),5))}
E19: {=IF(ISBLANK($B19),"", INDEX(itemCategoryDetails,MATCH($B19,INDEX(itemCategoryDetails,,2),0),5))}
B20: Catatan : | F20: Nomor PO :
B23: Diterima Oleh, | C23: Pengangkut, | E23: Hormat Kami,
B24: _____________________ | C24: =F6 -> Sugiyono | E24: Rizki Kurniawan
A26: PERATURAN PENYERAHAN GAS DAN PEMINJAMAN BOTOL
A27: 1. Pelanggan wajib memeriksa botol pada waktu menerima dan pada waktu mengembalikan botol kosong bersama petugas pengiriman. 2. Botol berisi yang sudah diterima baik, tidak dapat dikembalikan/diklaim mengenai tekanan/isinya, kecuali memang terdapat kebocoran botol dan lain lain oleh pihak PT Atma Karsa Gasindo. 3. Selama dalam waktu peminjaman, untuk setiap (1) kali periode pengisian, botol harus dikembalikan selambat-lambatnya 60 (enam puluh) hari sejak tanggal penyerahan, dan pihak PT Atma Karsa Gasindo akan mengirimkan surat konfirmasi pinjaman tabung lama 30 (tiga puluh) hari sebelum kadaluarsa. Keterlambatan pengembalian botol, baik untuk setiap periode pengisian maupun pada saat jangka waktu peminjaman telah berakhir, Pelanggan akan dikenakan tambahan biaya sewa dengan tarif botol/hari sebagai berikut : | D27: 4. Pelanggan tidak diperkenankan memodifikasi isi dan tampilan botol; memperjual belikan kembali botol; dipinjamkan dan dipindah-tangankan hak milik kepada pihak lain. 5. Pelanggan bertanggung jawab terhadap botol yang diterimanya/dipinjamnya. Pihak PT Atma Karsa Gasindo akan memberi surat peringatan apabila botol terindikasi hilang untuk memberi batas waktu pencarian kepada pelanggan. Apabila dalam waktu 3 (tiga) bulan sejak tanggal penyerahan belum dikembalikan, maka botol dinyatakan hilang dan pelanggan wajib membayar ganti rugi tunai sebesar :
D35: LPG | 50 Kg | F35: 2500000
D36: O2/N2/CO2/Ar | 7m3 | F36: 2500000
D37: O2/N2/CO2/Ar | 6m3 | F37: 2000000
D38: LPG | 12 Kg | F38: 2000000
D39: Acetylene | F39: 2000000
A40: LPG | 50 Kg | C40: 2000 | D40: Kran Botol | F40: 150000
A41: O2/N2/CO2/Ar | 7m3 | C41: 1500 | F41: =IMAGE("https://quickchart.io/qr?text=" & ENCODEURL(F3))
A42: O2/N2/CO2/Ar | 6m3 | C42: 1000
A43: LPG | 12 Kg | C43: 1000
A44: Acetylene | C44: 1000
A45: Dibuat pada tanggal 1 November 2024 dan dapat berubah sewaktu-waktu.
C47: PUTIH (FINANCE-AKG/LUNAS) MERAH (ADM-AKG) KUNING (RELASI) HIJAU (OPT)

Sheet Faktur Masa (Print)
F3: Kepada Yth :
F4: {=IFERROR(INDEX(customerDetails,MATCH(C13,INDEX(customerDetails,,1),0),2),"")} -> Bpk. Kadir (Maintenance Velg)
F5: {=IFERROR(INDEX(customerDetails,MATCH($C$13,INDEX(customerDetails,,1),0),5),"")} -> Jl. Lkr. Bypass Krian Timur, Sidogolong, Watugolong, Kec. Krian, Kabupaten Sidoarjo, Jawa Timur 61262
A6: Jl. Parengan Kali 19, Parengan, Kraton, Kec. Krian, Kab. Sidoarjo, Jawa Timur Telp : 085655863676 Email : atmakarsa.id@gmail.com
A11: FAKTUR PENJUALAN
A12: NPWP | C12: {=IFERROR(INDEX(customerDetails,MATCH(C13,INDEX(customerDetails,,1),0),3),"")} | E12: No. Faktur | F12: 2260314
A13: ID Pelanggan | C13: {=INDEX(customInv,MATCH($F$12,INDEX(customInv,,1),0),3)} -> ec231cc9 | E13: Tgl. Faktur | F13: =IFERROR(__xludf.DUMMYFUNCTION("INDEX(TEXT(SORT(QUERY(customInv,""SELECT AQ WHERE AL='""&$F$12&""'""),1,FALSE),""DD/MM/YYYY""),1,1)"),"17/04/2026") -> 17/04/2026
A14: No. PO | E14: Batas Pembayaran | F14: {=F13 + INDEX(customerDetails,MATCH(C13,INDEX(customerDetails,,1),0),6)} -> 46143
A16: No | B16: Nama Barang | D16: Satuan | E16: Kuantitas | F16: Harga Satuan | G16: Jumlah
A17: {=IFERROR(SEQUENCE(COUNTA(B17:B24),1),"")} -> 1 | B17: =IFERROR(__xludf.DUMMYFUNCTION("UNIQUE(FILTER( database!G2:G53, ISNUMBER(MATCH(database!B2:B53,ARRAYFORMULA(SPLIT(REGEXREPLACE(A36,""(\d+)"",""'$1""),"" "")) , 0)) )) "),"Oksigen 6m3") -> Oksigen 6m3 | D17: {=IF(ISBLANK($B17),"", INDEX(itemCategoryDetails,MATCH($B17,INDEX(itemCategoryDetails,,2),0),5))} -> Btl | E17: =IFERROR(__xludf.DUMMYFUNCTION("IF(ISBLANK($B17),"""",SUM(FILTER( database!$J$2:$J53, ISNUMBER(MATCH(database!$B$2:$B53,ARRAYFORMULA(SPLIT(REGEXREPLACE($A$36,""(\d+)"",""'$1""),"" "")) , 0)),database!$G$2:$G53=$B17 )))"),16.0) -> 16 | F17: =IFERROR(__xludf.DUMMYFUNCTION("IF(ISBLANK($B17),"""",INDEX(FILTER( database!$L$2:$L53, ISNUMBER(MATCH(database!$B$2:$B53,ARRAYFORMULA(SPLIT(REGEXREPLACE($A$36,""(\d+)"",""'$1""),"" "")) , 0)),database!$G$2:$G53=$B17 ),1,))"),55000.0) -> 55000 | G17: =IF(ISBLANK($B17),"",$E17*$F17) -> 880000
A18: 2 | B18: =IFERROR(__xludf.DUMMYFUNCTION("""COMPUTED_VALUE"""),"Karbondioksida") -> Karbondioksida | D18: {=IF(ISBLANK($B18),"", INDEX(itemCategoryDetails,MATCH($B18,INDEX(itemCategoryDetails,,2),0),5))} -> Btl | E18: =IFERROR(__xludf.DUMMYFUNCTION("IF(ISBLANK($B18),"""",SUM(FILTER( database!$J$2:$J53, ISNUMBER(MATCH(database!$B$2:$B53,ARRAYFORMULA(SPLIT(REGEXREPLACE($A$36,""(\d+)"",""'$1""),"" "")) , 0)),database!$G$2:$G53=$B18 )))"),5.0) -> 5 | F18: =IFERROR(__xludf.DUMMYFUNCTION("IF(ISBLANK($B18),"""",INDEX(FILTER( database!$L$2:$L53, ISNUMBER(MATCH(database!$B$2:$B53,ARRAYFORMULA(SPLIT(REGEXREPLACE($A$36,""(\d+)"",""'$1""),"" "")) , 0)),database!$G$2:$G53=$B18 ),1,))"),175000.0) -> 175000 | G18: =IF(ISBLANK($B18),"",$E18*$F18) -> 875000
A19: 3 | B19: =IFERROR(__xludf.DUMMYFUNCTION("""COMPUTED_VALUE"""),"Oksigen 7m3") -> Oksigen 7m3 | D19: {=IF(ISBLANK($B19),"", INDEX(itemCategoryDetails,MATCH($B19,INDEX(itemCategoryDetails,,2),0),5))} -> Btl | E19: =IFERROR(__xludf.DUMMYFUNCTION("IF(ISBLANK($B19),"""",SUM(FILTER( database!$J$2:$J53, ISNUMBER(MATCH(database!$B$2:$B53,ARRAYFORMULA(SPLIT(REGEXREPLACE($A$36,""(\d+)"",""'$1""),"" "")) , 0)),database!$G$2:$G53=$B19 )))"),1.0) -> 1 | F19: =IFERROR(__xludf.DUMMYFUNCTION("IF(ISBLANK($B19),"""",INDEX(FILTER( database!$L$2:$L53, ISNUMBER(MATCH(database!$B$2:$B53,ARRAYFORMULA(SPLIT(REGEXREPLACE($A$36,""(\d+)"",""'$1""),"" "")) , 0)),database!$G$2:$G53=$B19 ),1,))"),55000.0) -> 55000 | G19: =IF(ISBLANK($B19),"",$E19*$F19) -> 55000
D20: {=IF(ISBLANK($B20),"", INDEX(itemCategoryDetails,MATCH($B20,INDEX(itemCategoryDetails,,2),0),5))} | E20: =IFERROR(__xludf.DUMMYFUNCTION("IF(ISBLANK($B20),"""",SUM(FILTER( database!$J$2:$J53, ISNUMBER(MATCH(database!$B$2:$B53,ARRAYFORMULA(SPLIT(REGEXREPLACE($A$36,""(\d+)"",""'$1""),"" "")) , 0)),database!$G$2:$G53=$B20 )))"),"") | F20: =IFERROR(__xludf.DUMMYFUNCTION("IF(ISBLANK($B20),"""",INDEX(FILTER( database!$L$2:$L53, ISNUMBER(MATCH(database!$B$2:$B53,ARRAYFORMULA(SPLIT(REGEXREPLACE($A$36,""(\d+)"",""'$1""),"" "")) , 0)),database!$G$2:$G53=$B20 ),1,))")," ") | G20: =IF(ISBLANK($B20),"",$E20*$F20)
D21: {=IF(ISBLANK($B21),"", INDEX(itemCategoryDetails,MATCH($B21,INDEX(itemCategoryDetails,,2),0),5))} | E21: =IFERROR(__xludf.DUMMYFUNCTION("IF(ISBLANK($B21),"""",SUM(FILTER( database!$J$2:$J53, ISNUMBER(MATCH(database!$B$2:$B53,ARRAYFORMULA(SPLIT(REGEXREPLACE($A$36,""(\d+)"",""'$1""),"" "")) , 0)),database!$G$2:$G53=$B21 )))"),"") | F21: =IFERROR(__xludf.DUMMYFUNCTION("IF(ISBLANK($B21),"""",INDEX(FILTER( database!$L$2:$L53, ISNUMBER(MATCH(database!$B$2:$B53,ARRAYFORMULA(SPLIT(REGEXREPLACE($A$36,""(\d+)"",""'$1""),"" "")) , 0)),database!$G$2:$G53=$B21 ),1,))")," ") | G21: =IF(ISBLANK($B21),"",$E21*$F21)
D22: {=IF(ISBLANK($B22),"", INDEX(itemCategoryDetails,MATCH($B22,INDEX(itemCategoryDetails,,2),0),5))} | E22: =IFERROR(__xludf.DUMMYFUNCTION("IF(ISBLANK($B22),"""",SUM(FILTER( database!$J$2:$J53, ISNUMBER(MATCH(database!$B$2:$B53,ARRAYFORMULA(SPLIT(REGEXREPLACE($A$36,""(\d+)"",""'$1""),"" "")) , 0)),database!$G$2:$G53=$B22 )))"),"") | F22: =IFERROR(__xludf.DUMMYFUNCTION("IF(ISBLANK($B22),"""",INDEX(FILTER( database!$L$2:$L53, ISNUMBER(MATCH(database!$B$2:$B53,ARRAYFORMULA(SPLIT(REGEXREPLACE($A$36,""(\d+)"",""'$1""),"" "")) , 0)),database!$G$2:$G53=$B22 ),1,))")," ") | G22: =IF(ISBLANK($B22),"",$E22*$F22)
D23: {=IF(ISBLANK($B23),"", INDEX(itemCategoryDetails,MATCH($B23,INDEX(itemCategoryDetails,,2),0),5))} | E23: =IFERROR(__xludf.DUMMYFUNCTION("IF(ISBLANK($B23),"""",SUM(FILTER( database!$J$2:$J53, ISNUMBER(MATCH(database!$B$2:$B53,ARRAYFORMULA(SPLIT(REGEXREPLACE($A$36,""(\d+)"",""'$1""),"" "")) , 0)),database!$G$2:$G53=$B23 )))"),"") | F23: =IFERROR(__xludf.DUMMYFUNCTION("IF(ISBLANK($B23),"""",INDEX(FILTER( database!$L$2:$L53, ISNUMBER(MATCH(database!$B$2:$B53,ARRAYFORMULA(SPLIT(REGEXREPLACE($A$36,""(\d+)"",""'$1""),"" "")) , 0)),database!$G$2:$G53=$B23 ),1,))")," ") | G23: =IF(ISBLANK($B23),"",$E23*$F23)
D24: {=IF(ISBLANK($B24),"", INDEX(itemCategoryDetails,MATCH($B24,INDEX(itemCategoryDetails,,2),0),5))} | E24: =IFERROR(__xludf.DUMMYFUNCTION("IF(ISBLANK($B24),"""",SUM(FILTER( database!$J$2:$J53, ISNUMBER(MATCH(database!$B$2:$B53,ARRAYFORMULA(SPLIT(REGEXREPLACE($A$36,""(\d+)"",""'$1""),"" "")) , 0)),database!$G$2:$G53=$B24 )))"),"") | F24: =IFERROR(__xludf.DUMMYFUNCTION("IF(ISBLANK($B24),"""",INDEX(FILTER( database!$L$2:$L53, ISNUMBER(MATCH(database!$B$2:$B53,ARRAYFORMULA(SPLIT(REGEXREPLACE($A$36,""(\d+)"",""'$1""),"" "")) , 0)),database!$G$2:$G53=$B24 ),1,))")," ") | G24: =IF(ISBLANK($B24),"",$E24*$F24)
E25: Harga Jual | G25: =SUM(G17:G24) -> 1810000
E26: Potongan Harga
E27: Uang Muka Diterima
E28: Dasar Pengenaan Pajak | G28: =IFERROR(__xludf.DUMMYFUNCTION("IFERROR(IF(INDEX(customerDetails,MATCH(C13,INDEX(customerDetails,,1),0),4)=TRUE,G25-IFERROR(SUM(QUERY($B$17:$G$24,""SELECT G WHERE B CONTAINS 'Non PPN'"")),0),""""))")," ")
E29: PPN 11% | G29: {=IFERROR(IF(INDEX(customerDetails,MATCH(C13,INDEX(customerDetails,,1),0),4)=TRUE,$G28*11/100,""),"")}
E30: Jumlah yang Harus Dibayarkan | G30: =round(G25+G29,0) -> 1810000
A32: Catatan : | F32: ="Sidoarjo,"&" "&text(F13,"dd mmmm yyy") -> Sidoarjo, 17 April 2026
A33: =IFERROR(__xludf.DUMMYFUNCTION("CONCATENATE(""Pengiriman periode "","" "",INDEX(TEXT(SORT(QUERY(customInv,""SELECT AQ WHERE AL='""&$F$12&""'""),1,TRUE),""DD MMMM YYYY""),1,1),"" - "",INDEX(TEXT(SORT(QUERY(customInv,""SELECT AQ WHERE AL='""&$F$12&""'""),1,TRUE),""DD MMMM YYYY""),COUNT(QU"&"ERY(customInv,""SELECT AQ WHERE AL='""&$F$12&""'"")),1))"),"Pengiriman periode 01 April 2026 - 17 April 2026") -> Pengiriman periode 01 April 2026 - 17 April 2026
A35: Referensi :
A36: =IFERROR(__xludf.DUMMYFUNCTION("JOIN("" "",QUERY(customInv,""SELECT AM WHERE AL='""&$F$12&""' ORDER BY AQ DESC""))"),"0426533113 0426523078 0426513006 0426502950") -> 0426533113 0426523078 0426513006 0426502950
F37: Wahyono
B46: =IMAGE("https://qris.interactive.co.id/restapi/qris/show_qris.php") | G46: =IMAGE("https://quickchart.io/qr?text=" & ENCODEURL($F$12))
A49: Mohon sertakan nomor faktur pada berita/note. Pembayaran sah apabila terdapat bukti transfer ke :
B51: BRI | C51: 055301001926309 (Atma Karsa Gasindo)
B52: BNI | C52: 1895607235 (Atma Karsa Gasindo)
B53: BCA | C53: 1841622478 (Rizki Kurniawan) | F53: Customer Service : | G53: WA 081333292028

Sheet FakturMasa_Soft
F3: Kepada Yth :
F4: {=IFERROR(INDEX(customerDetails,MATCH(C13,INDEX(customerDetails,,1),0),2),"")} -> Bpk. Kadir (Maintenance Velg)
F5: {=IFERROR(INDEX(customerDetails,MATCH($C$13,INDEX(customerDetails,,1),0),5),"")} -> Jl. Lkr. Bypass Krian Timur, Sidogolong, Watugolong, Kec. Krian, Kabupaten Sidoarjo, Jawa Timur 61262
A6: Jl. Parengan Kali 19, Parengan, Kraton, Kec. Krian, Kab. Sidoarjo, Jawa Timur Telp : 085655863676 Email : atmakarsa.id@gmail.com
A11: FAKTUR PENJUALAN
A12: NPWP | C12: {=IFERROR(INDEX(customerDetails,MATCH(C13,INDEX(customerDetails,,1),0),3),"")} | E12: No. Faktur | F12: ='Faktur Masa (Print)'!$F$12 -> 2260314
A13: ID Pelanggan | C13: {=INDEX(customInv,MATCH($F$12,INDEX(customInv,,1),0),3)} -> ec231cc9 | E13: Tgl. Faktur | F13: =IFERROR(__xludf.DUMMYFUNCTION("INDEX(TEXT(SORT(QUERY(customInv,""SELECT AQ WHERE AL='""&$F$12&""'""),1,FALSE),""DD/MM/YYYY""),1,1)"),"17/04/2026") -> 17/04/2026
A14: No. PO | E14: Batas Pembayaran | F14: {=F13 + INDEX(customerDetails,MATCH(C13,INDEX(customerDetails,,1),0),6)} -> 46143
A16: No | B16: Nama Barang | D16: Satuan | E16: Kuantitas | F16: Harga Satuan | G16: Jumlah
A17: {=IFERROR(SEQUENCE(COUNTA(B17:B22),1),"")} -> 1 | B17: =IFERROR(__xludf.DUMMYFUNCTION("UNIQUE(FILTER( database!G2:G56, ISNUMBER(MATCH(database!B2:B56,ARRAYFORMULA(SPLIT(REGEXREPLACE(A36,""(\d+)"",""'$1""),"" "")) , 0)) )) "),"Oksigen 6m3") -> Oksigen 6m3 | D17: {=IF(ISBLANK($B17),"", INDEX(itemCategoryDetails,MATCH($B17,INDEX(itemCategoryDetails,,2),0),5))} -> Btl | E17: =IFERROR(__xludf.DUMMYFUNCTION("IF(ISBLANK($B17),"""",SUM(FILTER( database!$J$2:$J56, ISNUMBER(MATCH(database!$B$2:$B56,ARRAYFORMULA(SPLIT(REGEXREPLACE($A$36,""(\d+)"",""'$1""),"" "")) , 0)),database!$G$2:$G56=$B17 )))"),16.0) -> 16 | F17: =IFERROR(__xludf.DUMMYFUNCTION("IF(ISBLANK($B17),"""",INDEX(FILTER( database!$L$2:$L56, ISNUMBER(MATCH(database!$B$2:$B56,ARRAYFORMULA(SPLIT(REGEXREPLACE($A$36,""(\d+)"",""'$1""),"" "")) , 0)),database!$G$2:$G56=$B17 ),1,))"),55000.0) -> 55000 | G17: =IF(ISBLANK($B17),"",$E17*$F17) -> 880000
A18: 2 | B18: =IFERROR(__xludf.DUMMYFUNCTION("""COMPUTED_VALUE"""),"Karbondioksida") -> Karbondioksida | D18: {=IF(ISBLANK($B18),"", INDEX(itemCategoryDetails,MATCH($B18,INDEX(itemCategoryDetails,,2),0),5))} -> Btl | E18: =IFERROR(__xludf.DUMMYFUNCTION("IF(ISBLANK($B18),"""",SUM(FILTER( database!$J$2:$J56, ISNUMBER(MATCH(database!$B$2:$B56,ARRAYFORMULA(SPLIT(REGEXREPLACE($A$36,""(\d+)"",""'$1""),"" "")) , 0)),database!$G$2:$G56=$B18 )))"),5.0) -> 5 | F18: =IFERROR(__xludf.DUMMYFUNCTION("IF(ISBLANK($B18),"""",INDEX(FILTER( database!$L$2:$L56, ISNUMBER(MATCH(database!$B$2:$B56,ARRAYFORMULA(SPLIT(REGEXREPLACE($A$36,""(\d+)"",""'$1""),"" "")) , 0)),database!$G$2:$G56=$B18 ),1,))"),175000.0) -> 175000 | G18: =IF(ISBLANK($B18),"",$E18*$F18) -> 875000
A19: 3 | B19: =IFERROR(__xludf.DUMMYFUNCTION("""COMPUTED_VALUE"""),"Oksigen 7m3") -> Oksigen 7m3 | D19: {=IF(ISBLANK($B19),"", INDEX(itemCategoryDetails,MATCH($B19,INDEX(itemCategoryDetails,,2),0),5))} -> Btl | E19: =IFERROR(__xludf.DUMMYFUNCTION("IF(ISBLANK($B19),"""",SUM(FILTER( database!$J$2:$J56, ISNUMBER(MATCH(database!$B$2:$B56,ARRAYFORMULA(SPLIT(REGEXREPLACE($A$36,""(\d+)"",""'$1""),"" "")) , 0)),database!$G$2:$G56=$B19 )))"),1.0) -> 1 | F19: =IFERROR(__xludf.DUMMYFUNCTION("IF(ISBLANK($B19),"""",INDEX(FILTER( database!$L$2:$L56, ISNUMBER(MATCH(database!$B$2:$B56,ARRAYFORMULA(SPLIT(REGEXREPLACE($A$36,""(\d+)"",""'$1""),"" "")) , 0)),database!$G$2:$G56=$B19 ),1,))"),55000.0) -> 55000 | G19: =IF(ISBLANK($B19),"",$E19*$F19) -> 55000
D20: {=IF(ISBLANK($B20),"", INDEX(itemCategoryDetails,MATCH($B20,INDEX(itemCategoryDetails,,2),0),5))} | E20: =IFERROR(__xludf.DUMMYFUNCTION("IF(ISBLANK($B20),"""",SUM(FILTER( database!$J$2:$J56, ISNUMBER(MATCH(database!$B$2:$B56,ARRAYFORMULA(SPLIT(REGEXREPLACE($A$36,""(\d+)"",""'$1""),"" "")) , 0)),database!$G$2:$G56=$B20 )))"),"") | F20: =IFERROR(__xludf.DUMMYFUNCTION("IF(ISBLANK($B20),"""",INDEX(FILTER( database!$L$2:$L56, ISNUMBER(MATCH(database!$B$2:$B56,ARRAYFORMULA(SPLIT(REGEXREPLACE($A$36,""(\d+)"",""'$1""),"" "")) , 0)),database!$G$2:$G56=$B20 ),1,))")," ") | G20: =IF(ISBLANK($B20),"",$E20*$F20)
F21: =IFERROR(__xludf.DUMMYFUNCTION("IF(ISBLANK($B21),"""",INDEX(FILTER( database!$L$2:$L56, ISNUMBER(MATCH(database!$B$2:$B56,ARRAYFORMULA(SPLIT(REGEXREPLACE($A$36,""(\d+)"",""'$1""),"" "")) , 0)),database!$G$2:$G56=$B21 ),1,))")," ")
D22: {=IF(ISBLANK($B22),"", INDEX(itemCategoryDetails,MATCH($B22,INDEX(itemCategoryDetails,,2),0),5))} | E22: =IFERROR(__xludf.DUMMYFUNCTION("IF(ISBLANK($B22),"""",SUM(FILTER( database!$J$2:$J56, ISNUMBER(MATCH(database!$B$2:$B56,ARRAYFORMULA(SPLIT(REGEXREPLACE($A$36,""(\d+)"",""'$1""),"" "")) , 0)),database!$G$2:$G56=$B22 )))"),"") | F22: =IFERROR(__xludf.DUMMYFUNCTION("IF(ISBLANK($B22),"""",INDEX(FILTER( database!$L$2:$L56, ISNUMBER(MATCH(database!$B$2:$B56,ARRAYFORMULA(SPLIT(REGEXREPLACE($A$36,""(\d+)"",""'$1""),"" "")) , 0)),database!$G$2:$G56=$B22 ),1,))")," ") | G22: =IF(ISBLANK($B22),"",$E22*$F22)
F23: =IFERROR(__xludf.DUMMYFUNCTION("IF(ISBLANK($B23),"""",INDEX(FILTER( database!$L$2:$L56, ISNUMBER(MATCH(database!$B$2:$B56,ARRAYFORMULA(SPLIT(REGEXREPLACE($A$36,""(\d+)"",""'$1""),"" "")) , 0)),database!$G$2:$G56=$B23 ),1,))")," ")
F24: =IFERROR(__xludf.DUMMYFUNCTION("IF(ISBLANK($B24),"""",INDEX(FILTER( database!$L$2:$L56, ISNUMBER(MATCH(database!$B$2:$B56,ARRAYFORMULA(SPLIT(REGEXREPLACE($A$36,""(\d+)"",""'$1""),"" "")) , 0)),database!$G$2:$G56=$B24 ),1,))")," ")
E25: Harga Jual | G25: =SUM($G$17:$G$24) -> 1810000
E26: Potongan Harga
E27: Uang Muka Diterima
E28: Dasar Pengenaan Pajak | G28: =IFERROR(__xludf.DUMMYFUNCTION("IFERROR(IF(INDEX(customerDetails,MATCH(C13,INDEX(customerDetails,,1),0),4)=TRUE,G25-IFERROR(SUM(QUERY($B$17:$G$24,""SELECT G WHERE B CONTAINS 'Non PPN'"")),0),""""))")," ")
E29: PPN 11% | G29: {=IFERROR(IF(INDEX(customerDetails,MATCH(C13,INDEX(customerDetails,,1),0),4)=TRUE,$G28*11/100,""),"")}
E30: Jumlah yang Harus Dibayarkan | G30: =round(G25+G29,0) -> 1810000
A32: Catatan : | F32: ="Sidoarjo,"&" "&text(F13,"dd mmmm yyy") -> Sidoarjo, 17 April 2026
A33: =IFERROR(__xludf.DUMMYFUNCTION("CONCATENATE(""Pengiriman periode "","" "",INDEX(TEXT(SORT(QUERY(customInv,""SELECT AQ WHERE AL='""&$F$12&""'""),1,TRUE),""DD MMMM YYYY""),1,1),"" - "",INDEX(TEXT(SORT(QUERY(customInv,""SELECT AQ WHERE AL='""&$F$12&""'""),1,TRUE),""DD MMMM YYYY""),COUNT(QU"&"ERY(customInv,""SELECT AQ WHERE AL='""&$F$12&""'"")),1))"),"Pengiriman periode 01 April 2026 - 17 April 2026") -> Pengiriman periode 01 April 2026 - 17 April 2026
A35: Referensi :
A36: =IFERROR(__xludf.DUMMYFUNCTION("JOIN("" "",QUERY(customInv,""SELECT AM WHERE AL='""&$F$12&""' ORDER BY AQ DESC""))"),"0426533113 0426523078 0426513006 0426502950") -> 0426533113 0426523078 0426513006 0426502950
F38: Wahyono
B49: =IMAGE("https://qris.interactive.co.id/restapi/qris/show_qris.php") | G49: =IMAGE("https://quickchart.io/qr?text=" & ENCODEURL($F$12))
A52: Mohon sertakan nomor faktur pada berita/note. Pembayaran sah apabila terdapat bukti transfer ke :
B54: BRI | C54: 055301001926309 (Atma Karsa Gasindo)
B55: BNI | C55: 1895607235 (Atma Karsa Gasindo)
B56: BCA | C56: 1841622478 (Rizki Kurniawan) | F56: Customer Service : | G56: WA 081333292028

Sheet Purchases Order
H3: PURCHASE ORDER
H4: Nomor
H5: Tanggal
B6: Jl. Parengan Kali 19, Parengan, Kraton, Kec. Krian, Kab. Sidoarjo, Jawa Timur Telp : 085655863676 Email : atmakarsa.id@gmail.com | H6: Tanggal Kirim
B12: Kepada : | G12: PIC PO :
B15: Tujuan : | G15: Mohon Dikirimkan Ke :
B19: No | C19: Nama Barang | E19: Satuan | F19: Kuantitas | G19: Harga Satuan | H19: Jumlah
B24: TOP : | G24: Harga Jual
G25: Potongan Harga
G26: Uang Muka Diterima
B27: Catatan : | G27: Dasar Pengenaan Pajak
G28: PPN 11%
G29: Jumlah yang Harus Dibayarkan
G31: ="Sidoarjo," -> Sidoarjo,
G36: Wahyono

Sheet Surat Jalan Lain
E1: Surat Jalan | F1: {=INDEX(inventoryLog,MATCH($F$3,INDEX(inventoryLog,,2),0),9)} -> EMPTY
E3: Nomor Dokumen | F3: 4042612928
E4: Tanggal | F4: {=INDEX(documentLog,MATCH($F$3,INDEX(documentLog,,2),0),5)} -> 46116.362
A5: Jl. Parengan Kali 19, Parengan, Kraton, Kec. Krian, Kab. Sidoarjo, Jawa Timur Telp : 085655863676 Email : atmakarsa.id@gmail.com | E5: No. Polisi | F5: L 8314 JQ
E6: Driver | F6: Sugiyono
E7: Telp. Driver | F7: 085850403150
A10: Alamat : | D10: Kepada Yth :
A11: {=INDEX(documentLog,MATCH($F$3,INDEX(documentLog,,2),0),6)} -> Jl. Bypass Krian, Kraton, Kec. Krian, Kabupaten Sidoarjo, Jawa Timur 61262 | D11: {=INDEX(documentLog,MATCH($F$3,INDEX(documentLog,,2),0),4)} -> UD. Ais Jaya
A13: No | B13: Nama Barang | E13: Satuan | F13: Jumlah
A15: {=IFERROR(SEQUENCE(COUNTA(B15:B19),1),"")} -> 1 | B15: =IFERROR(__xludf.DUMMYFUNCTION("QUERY(inventoryLog,""SELECT G,K WHERE B='""&F3&""'"",)"),"Oksigen 6m3") -> Oksigen 6m3 | C15: =IFERROR(__xludf.DUMMYFUNCTION("""COMPUTED_VALUE"""),"11120") -> 11120 | E15: =IF(B15<>"", "Btl", "") -> Btl | F15: =IFERROR(__xludf.DUMMYFUNCTION("QUERY(inventoryLog,""SELECT J WHERE B='""&F3&""'"",)"),1.0) -> 1
E16: =IF(B16<>"", "Btl", "")
E17: =IF(B17<>"", "Btl", "")
E18: =IF(B18<>"", "Btl", "")
E19: =IF(B19<>"", "Btl", "")
B20: Catatan : | F20: Nomor PO :
B23: Diterima Oleh, | C23: Pengangkut, | E23: Hormat Kami,
B24: _____________________ | C24: =F6 -> Sugiyono | E24: Rizki Kurniawan
A26: PERATURAN PENYERAHAN GAS DAN PEMINJAMAN BOTOL
A27: 1. Pelanggan wajib memeriksa botol pada waktu menerima dan pada waktu mengembalikan botol kosong bersama petugas pengiriman. 2. Botol berisi yang sudah diterima baik, tidak dapat dikembalikan/diklaim mengenai tekanan/isinya, kecuali memang terdapat kebocoran botol dan lain lain oleh pihak PT Atma Karsa Gasindo. 3. Selama dalam waktu peminjaman, untuk setiap (1) kali periode pengisian, botol harus dikembalikan selambat-lambatnya 60 (enam puluh) hari sejak tanggal penyerahan, dan pihak PT Atma Karsa Gasindo akan mengirimkan surat konfirmasi pinjaman tabung lama 30 (tiga puluh) hari sebelum kadaluarsa. Keterlambatan pengembalian botol, baik untuk setiap periode pengisian maupun pada saat jangka waktu peminjaman telah berakhir, Pelanggan akan dikenakan tambahan biaya sewa dengan tarif botol/hari sebagai berikut : | D27: 4. Pelanggan tidak diperkenankan memodifikasi isi dan tampilan botol; memperjual belikan kembali botol; dipinjamkan dan dipindah-tangankan hak milik kepada pihak lain. 5. Pelanggan bertanggung jawab terhadap botol yang diterimanya/dipinjamnya. Pihak PT Atma Karsa Gasindo akan memberi surat peringatan apabila botol terindikasi hilang untuk memberi batas waktu pencarian kepada pelanggan. Apabila dalam waktu 3 (tiga) bulan sejak tanggal penyerahan belum dikembalikan, maka botol dinyatakan hilang dan pelanggan wajib membayar ganti rugi tunai sebesar :
D35: LPG | 50 Kg | F35: 2500000
D36: O2/N2/CO2/Ar | 7m3 | F36: 2500000
D37: O2/N2/CO2/Ar | 6m3 | F37: 2000000
D38: LPG | 12 Kg | F38: 2000000
D39: Acetylene | F39: 2000000
A40: LPG | 50 Kg | C40: 2000 | D40: Kran Botol | F40: 150000
A41: O2/N2/CO2/Ar | 7m3 | C41: 1500 | F41: =IMAGE("https://quickchart.io/qr?text=" & ENCODEURL(F3))
A42: O2/N2/CO2/Ar | 6m3 | C42: 1000
A43: LPG | 12 Kg | C43: 1000
A44: Acetylene | C44: 1000
A45: Dibuat pada tanggal 1 November 2024 dan dapat berubah sewaktu-waktu.

Sheet Faktur Masa Custom Date
F3: Kepada Yth :
F4: {=IFERROR(INDEX(customerDetails,MATCH(C13,INDEX(customerDetails,,1),0),2),"")} -> PT Sinar Indogreen Kencana
F5: {=IFERROR(INDEX(customerDetails,MATCH($C$13,INDEX(customerDetails,,1),0),5),"")} -> Jl. Raya Ponokawan 8b RT/001 RW/002, Ponokawan, Krian, Sidoarjo
A6: Jl. Parengan Kali 19, Parengan, Kraton, Kec. Krian, Kab. Sidoarjo, Jawa Timur Telp : 085655863676 Email : atmakarsa.id@gmail.com
A11: FAKTUR PENJUALAN
A12: NPWP | C12: {=IFERROR(INDEX(customerDetails,MATCH(C13,INDEX(customerDetails,,1),0),3),"")} | E12: No. Faktur | F12: 2250042
A13: ID Pelanggan | C13: {=INDEX(customInv,MATCH($F$12,INDEX(customInv,,1),0),3)} -> d78b2eaf | E13: Tgl. Faktur | F13: 45901
A14: No. PO | E14: Batas Pembayaran | F14: =F13 + 29 -> 45930
A16: No | B16: Nama Barang | D16: Satuan | E16: Kuantitas | F16: Harga Satuan | G16: Jumlah
A17: {=IFERROR(SEQUENCE(COUNTA(B17:B22),1),"")} -> 1 | B17: =IFERROR(__xludf.DUMMYFUNCTION("UNIQUE(FILTER( database!G2:G53, ISNUMBER(MATCH(database!B2:B53,ARRAYFORMULA(SPLIT(REGEXREPLACE(A34,""(\d+)"",""'$1""),"" "")) , 0)) )) "),"LPG 12kg") -> LPG 12kg | D17: {=IF(ISBLANK($B17),"", INDEX(itemCategoryDetails,MATCH($B17,INDEX(itemCategoryDetails,,2),0),5))} -> Btl | E17: =IFERROR(__xludf.DUMMYFUNCTION("IF(ISBLANK($B17),"""",SUM(FILTER( database!$J$2:$J53, ISNUMBER(MATCH(database!$B$2:$B53,ARRAYFORMULA(SPLIT(REGEXREPLACE($A$34,""(\d+)"",""'$1""),"" "")) , 0)),database!$G$2:$G53=$B17 )))"),3.0) -> 3 | F17: =IFERROR(__xludf.DUMMYFUNCTION("IF(ISBLANK($B17),"""",INDEX(FILTER( database!$M$2:$M53, ISNUMBER(MATCH(database!$B$2:$B53,ARRAYFORMULA(SPLIT(REGEXREPLACE($A$34,""(\d+)"",""'$1""),"" "")) , 0)),database!$G$2:$G53=$B17 ),1,))"),"") | G17: =IF(ISBLANK($B17),"",$E17*$F17) -> 0
D18: {=IF(ISBLANK($B18),"", INDEX(itemCategoryDetails,MATCH($B18,INDEX(itemCategoryDetails,,2),0),5))} | E18: =IFERROR(__xludf.DUMMYFUNCTION("IF(ISBLANK($B18),"""",SUM(FILTER( database!$J$2:$J53, ISNUMBER(MATCH(database!$B$2:$B53,ARRAYFORMULA(SPLIT(REGEXREPLACE($A$34,""(\d+)"",""'$1""),"" "")) , 0)),database!$G$2:$G53=$B18 )))"),"") | F18: =IFERROR(__xludf.DUMMYFUNCTION("IF(ISBLANK($B18),"""",INDEX(FILTER( database!$M$2:$M53, ISNUMBER(MATCH(database!$B$2:$B53,ARRAYFORMULA(SPLIT(REGEXREPLACE($A$34,""(\d+)"",""'$1""),"" "")) , 0)),database!$G$2:$G53=$B18 ),1,))")," ") | G18: =IF(ISBLANK($B18),"",$E18*$F18)
D19: {=IF(ISBLANK($B19),"", INDEX(itemCategoryDetails,MATCH($B19,INDEX(itemCategoryDetails,,2),0),5))} | E19: =IFERROR(__xludf.DUMMYFUNCTION("IF(ISBLANK($B19),"""",SUM(FILTER( database!$J$2:$J53, ISNUMBER(MATCH(database!$B$2:$B53,ARRAYFORMULA(SPLIT(REGEXREPLACE($A$34,""(\d+)"",""'$1""),"" "")) , 0)),database!$G$2:$G53=$B19 )))"),"") | F19: =IFERROR(__xludf.DUMMYFUNCTION("IF(ISBLANK($B19),"""",INDEX(FILTER( database!$M$2:$M53, ISNUMBER(MATCH(database!$B$2:$B53,ARRAYFORMULA(SPLIT(REGEXREPLACE($A$34,""(\d+)"",""'$1""),"" "")) , 0)),database!$G$2:$G53=$B19 ),1,))")," ") | G19: =IF(ISBLANK($B19),"",$E19*$F19)
D20: {=IF(ISBLANK($B20),"", INDEX(itemCategoryDetails,MATCH($B20,INDEX(itemCategoryDetails,,2),0),5))} | E20: =IFERROR(__xludf.DUMMYFUNCTION("IF(ISBLANK($B20),"""",SUM(FILTER( database!$J$2:$J53, ISNUMBER(MATCH(database!$B$2:$B53,ARRAYFORMULA(SPLIT(REGEXREPLACE($A$34,""(\d+)"",""'$1""),"" "")) , 0)),database!$G$2:$G53=$B20 )))"),"") | F20: =IFERROR(__xludf.DUMMYFUNCTION("IF(ISBLANK($B20),"""",INDEX(FILTER( database!$M$2:$M53, ISNUMBER(MATCH(database!$B$2:$B53,ARRAYFORMULA(SPLIT(REGEXREPLACE($A$34,""(\d+)"",""'$1""),"" "")) , 0)),database!$G$2:$G53=$B20 ),1,))")," ") | G20: =IF(ISBLANK($B20),"",$E20*$F20)
D22: {=IF(ISBLANK($B22),"", INDEX(itemCategoryDetails,MATCH($B22,INDEX(itemCategoryDetails,,2),0),5))} | E22: =IFERROR(__xludf.DUMMYFUNCTION("IF(ISBLANK($B22),"""",SUM(FILTER( database!$J$2:$J53, ISNUMBER(MATCH(database!$B$2:$B53,ARRAYFORMULA(SPLIT(REGEXREPLACE($A$34,""(\d+)"",""'$1""),"" "")) , 0)),database!$G$2:$G53=$B22 )))"),"") | F22: =IFERROR(__xludf.DUMMYFUNCTION("IF(ISBLANK($B22),"""",INDEX(FILTER( database!$M$2:$M53, ISNUMBER(MATCH(database!$B$2:$B53,ARRAYFORMULA(SPLIT(REGEXREPLACE($A$34,""(\d+)"",""'$1""),"" "")) , 0)),database!$G$2:$G53=$B22 ),1,))")," ") | G22: =IF(ISBLANK($B22),"",$E22*$F22)
E23: Harga Jual | G23: =SUM(G17:G19) -> 0
E24: Potongan Harga
E25: Uang Muka Diterima
E26: Dasar Pengenaan Pajak | G26: {=IFERROR(IF(INDEX(customerDetails,MATCH(C13,INDEX(customerDetails,,1),0),4)=TRUE,G23,""),"")} -> 0
E27: PPN 11% | G27: {=IFERROR(IF(INDEX(customerDetails,MATCH(C13,INDEX(customerDetails,,1),0),4)=TRUE,$G26*11/100,""),"")} -> 0
E28: Jumlah yang Harus Dibayarkan | G28: =round(G23+G27,0) -> 0
A30: Catatan : | F30: ="Sidoarjo,"&" "&text(F13,"dd mmmm yyy") -> Sidoarjo, 01 September 2025
A31: =IFERROR(__xludf.DUMMYFUNCTION("CONCATENATE(""Pengiriman periode "","" "",INDEX(TEXT(SORT(QUERY(customInv,""SELECT AQ WHERE AL='""&$F$12&""'""),1,TRUE),""DD MMMM YYYY""),1,1),"" - "",INDEX(TEXT(SORT(QUERY(customInv,""SELECT AQ WHERE AL='""&$F$12&""'""),1,TRUE),""DD MMMM YYYY""),COUNT(QU"&"ERY(customInv,""SELECT AQ WHERE AL='""&$F$12&""'"")),1))"),"Pengiriman periode 21 Juli 2025 - 19 Agustus 2025") -> Pengiriman periode 21 Juli 2025 - 19 Agustus 2025
A33: Referensi :
A34: =IFERROR(__xludf.DUMMYFUNCTION("JOIN("" "",QUERY(customInv,""SELECT AM WHERE AL='""&$F$12&""' ORDER BY AQ DESC""))"),"0825131141 0825121111 07250593") -> 0825131141 0825121111 07250593
F35: Wahyono
B46: =IMAGE("https://qris.interactive.co.id/restapi/qris/show_qris.php") | G46: =IMAGE("https://quickchart.io/qr?text=" & ENCODEURL($F$12))
A50: Mohon sertakan nomor faktur pada berita/note. Pembayaran sah apabila terdapat bukti transfer ke :
B52: BNI | C52: 1895607235 (Atma Karsa Gasindo)
B53: BCA | C53: 1841622478 (Rizki Kurniawan) | F53: Customer Service : | G53: WA 081333292028

Sheet draftFAKTUR MASA & KWITANSI
F3: Kepada Yth :
F4: {=IFERROR(INDEX(customerDetails,MATCH(C13,INDEX(customerDetails,,1),0),2),"")} -> Mitra Wood Sejahtera
F5: {=IFERROR(INDEX(customerDetails,MATCH($C$13,INDEX(customerDetails,,1),0),5),"")} -> Jl.cungkling, Jl. Tanggungan, Nanom Kidul, Lebaniwaras, Kec. Wringinanom, Kabupaten Gresik, Jawa Timur 61176
A6: Jl. Parengan Kali 19, Parengan, Kraton, Kec. Krian, Kab. Sidoarjo, Jawa Timur Telp : 085655863676 Email : atmakarsa.id@gmail.com
A11: FAKTUR PENJUALAN
A12: NPWP | C12: {=IFERROR(INDEX(customerDetails,MATCH(C13,INDEX(customerDetails,,1),0),3),"")} | E12: No. Faktur | F12: 2250033
A13: ID Pelanggan | C13: {=INDEX(customInv,MATCH($F$12,INDEX(customInv,,1),0),3)} -> eec2e801 | E13: Tgl. Faktur | F13: =IFERROR(__xludf.DUMMYFUNCTION("INDEX(TEXT(SORT(QUERY(customInv,""SELECT AQ WHERE AL='""&$F$12&""'""),1,FALSE),""DD/MM/YYYY""),1,1)"),"23/07/2025") -> 23/07/2025
A14: No. PO | E14: Batas Pembayaran
A16: No | B16: Nama Barang | D16: Satuan | E16: Kuantitas | F16: Harga Satuan | G16: Jumlah
A17: {=IFERROR(SEQUENCE(COUNTA(B17:B21),1),"")} -> 1 | B17: =IFERROR(__xludf.DUMMYFUNCTION("UNIQUE(FILTER( database!G2:G53, ISNUMBER(MATCH(database!B2:B53,ARRAYFORMULA(SPLIT(REGEXREPLACE(A27,""(\d+)"",""'$1""),"" "")) , 0)) )) "),"Oksigen 6m3") -> Oksigen 6m3 | D17: {=IF(ISBLANK($B17),"", INDEX(itemCategoryDetails,MATCH($B17,INDEX(itemCategoryDetails,,2),0),5))} -> Btl | E17: =IFERROR(__xludf.DUMMYFUNCTION("IF(ISBLANK($B17),"""",SUM(FILTER( database!$J$2:$J53, ISNUMBER(MATCH(database!$B$2:$B53,ARRAYFORMULA(SPLIT(REGEXREPLACE($A$27,""(\d+)"",""'$1""),"" "")) , 0)),database!$G$2:$G53=$B17 )))"),20.0) -> 20 | F17: =IFERROR(__xludf.DUMMYFUNCTION("IF(ISBLANK($B17),"""",INDEX(FILTER( database!$M$2:$M53, ISNUMBER(MATCH(database!$B$2:$B53,ARRAYFORMULA(SPLIT(REGEXREPLACE($A$27,""(\d+)"",""'$1""),"" "")) , 0)),database!$G$2:$G53=$B17 ),1,))"),"") | G17: =IF(ISBLANK($B17),"",$E17*$F17) -> 0
A18: 2 | B18: =IFERROR(__xludf.DUMMYFUNCTION("""COMPUTED_VALUE"""),"LPG 12kg") -> LPG 12kg | D18: {=IF(ISBLANK($B18),"", INDEX(itemCategoryDetails,MATCH($B18,INDEX(itemCategoryDetails,,2),0),5))} -> Btl | E18: =IFERROR(__xludf.DUMMYFUNCTION("IF(ISBLANK($B18),"""",SUM(FILTER( database!$J$2:$J53, ISNUMBER(MATCH(database!$B$2:$B53,ARRAYFORMULA(SPLIT(REGEXREPLACE($A$27,""(\d+)"",""'$1""),"" "")) , 0)),database!$G$2:$G53=$B18 )))"),4.0) -> 4 | F18: =IFERROR(__xludf.DUMMYFUNCTION("IF(ISBLANK($B18),"""",INDEX(FILTER( database!$M$2:$M53, ISNUMBER(MATCH(database!$B$2:$B53,ARRAYFORMULA(SPLIT(REGEXREPLACE($A$27,""(\d+)"",""'$1""),"" "")) , 0)),database!$G$2:$G53=$B18 ),1,))"),"") | G18: =IF(ISBLANK($B18),"",$E18*$F18) -> 0
D19: {=IF(ISBLANK($B19),"", INDEX(itemCategoryDetails,MATCH($B19,INDEX(itemCategoryDetails,,2),0),5))} | E19: =IFERROR(__xludf.DUMMYFUNCTION("IF(ISBLANK($B19),"""",SUM(FILTER( database!$J$2:$J53, ISNUMBER(MATCH(database!$B$2:$B53,ARRAYFORMULA(SPLIT(REGEXREPLACE($A$27,""(\d+)"",""'$1""),"" "")) , 0)),database!$G$2:$G53=$B19 )))"),"") | F19: =IFERROR(__xludf.DUMMYFUNCTION("IF(ISBLANK($B19),"""",INDEX(FILTER( database!$M$2:$M53, ISNUMBER(MATCH(database!$B$2:$B53,ARRAYFORMULA(SPLIT(REGEXREPLACE($A$27,""(\d+)"",""'$1""),"" "")) , 0)),database!$G$2:$G53=$B19 ),1,))")," ") | G19: =IF(ISBLANK($B19),"",$E19*$F19)
D20: {=IF(ISBLANK($B20),"", INDEX(itemCategoryDetails,MATCH($B20,INDEX(itemCategoryDetails,,2),0),5))} | E20: =IFERROR(__xludf.DUMMYFUNCTION("IF(ISBLANK($B20),"""",SUM(FILTER( database!$J$2:$J53, ISNUMBER(MATCH(database!$B$2:$B53,ARRAYFORMULA(SPLIT(REGEXREPLACE($A$27,""(\d+)"",""'$1""),"" "")) , 0)),database!$G$2:$G53=$B20 )))"),"") | F20: =IFERROR(__xludf.DUMMYFUNCTION("IF(ISBLANK($B20),"""",INDEX(FILTER( database!$M$2:$M53, ISNUMBER(MATCH(database!$B$2:$B53,ARRAYFORMULA(SPLIT(REGEXREPLACE($A$27,""(\d+)"",""'$1""),"" "")) , 0)),database!$G$2:$G53=$B20 ),1,))")," ") | G20: =IF(ISBLANK($B20),"",$E20*$F20)
D21: {=IF(ISBLANK($B21),"", INDEX(itemCategoryDetails,MATCH($B21,INDEX(itemCategoryDetails,,2),0),5))} | E21: =IFERROR(__xludf.DUMMYFUNCTION("IF(ISBLANK($B21),"""",SUM(FILTER( database!$J$2:$J53, ISNUMBER(MATCH(database!$B$2:$B53,ARRAYFORMULA(SPLIT(REGEXREPLACE($A$27,""(\d+)"",""'$1""),"" "")) , 0)),database!$G$2:$G53=$B21 )))"),"") | F21: =IFERROR(__xludf.DUMMYFUNCTION("IF(ISBLANK($B21),"""",INDEX(FILTER( database!$M$2:$M53, ISNUMBER(MATCH(database!$B$2:$B53,ARRAYFORMULA(SPLIT(REGEXREPLACE($A$27,""(\d+)"",""'$1""),"" "")) , 0)),database!$G$2:$G53=$B21 ),1,))")," ") | G21: =IF(ISBLANK($B21),"",$E21*$F21)
E22: Harga Jual | G22: =SUM(G17:G19) -> 0
A23: Catatan : | E23: Ongkos Kirim
A24: =IFERROR(__xludf.DUMMYFUNCTION("CONCATENATE(""Pengiriman periode "","" "",INDEX(TEXT(SORT(QUERY(customInv,""SELECT AQ WHERE AL='""&$F$12&""'""),1,TRUE),""DD MMMM YYYY""),1,1),"" - "",INDEX(TEXT(SORT(QUERY(customInv,""SELECT AQ WHERE AL='""&$F$12&""'""),1,TRUE),""DD MMMM YYYY""),COUNT(QU"&"ERY(customInv,""SELECT AQ WHERE AL='""&$F$12&""'"")),1))"),"Pengiriman periode 23 Juli 2025 - 23 Juli 2025") -> Pengiriman periode 23 Juli 2025 - 23 Juli 2025 | E24: Potongan Harga
E25: Uang Muka Diterima
A26: Referensi : | E26: Dasar Pengenaan Pajak | G26: {=IFERROR(IF(INDEX(customerDetails,MATCH(C13,INDEX(customerDetails,,1),0),4)=TRUE,G22,""),"")}
A27: =IFERROR(__xludf.DUMMYFUNCTION("JOIN("" "",QUERY(customInv,""SELECT AM WHERE AL='""&$F$12&""' ORDER BY AQ DESC""))"),"07250602 07250604") -> 07250602 07250604 | E27: PPN 11% | G27: {=IFERROR(IF(INDEX(customerDetails,MATCH(C13,INDEX(customerDetails,,1),0),4)=TRUE,G22*11/100,""),"")}
E28: Jumlah yang Harus Dibayarkan | G28: =G22+G27+G23 -> 0
A30: =IMAGE("https://quickchart.io/qr?text=" & ENCODEURL($F$12)) | F30: ="Sidoarjo,"&" "&text(F13,"dd mmmm yyy") -> Sidoarjo, 23 Juli 2025
C31: Mohon sertakan nomor faktur pada berita/note. Pembayaran sah apabila terdapat bukti transfer ke :
C33: BNI 1895607235 (Atma Karsa Gasindo)
C34: BCA 1841622478 (Rizki Kurniawan)
F35: Wahyono
B46: =IMAGE("https://qris.interactive.co.id/restapi/qris/show_qris.php")

Sheet Tanda Terima (Connected Faktur)
F4: Tanda Terima
A6: Jl. Parengan Kali 19, Parengan, Kraton, Kec. Krian, Kab. Sidoarjo, Jawa Timur Telp : 085655863676 Email : atmakarsa.id@gmail.com
F7: Tanggal : | G7: 45757
A11: Telah terima | B11: : | C11: ="1. Faktur Penjualan" &" x1" -> 1. Faktur Penjualan x1
C12: =Faktur!F12 -> 04261063117
C13: ="2. Surat Jalan x1" -> 2. Surat Jalan x1
C14: =Faktur!F12 -> 04261063117
A17: Dari/Untuk | B17: : | C17: ='Faktur Masa (Print)'!$F$4 -> Bpk. Kadir (Maintenance Velg)
A19: Yang menyerahkan, | F19: Penerima,

Sheet Tanda Terima (Connected Faktur 
F4: Tanda Terima
A6: Jl. Parengan Kali 19, Parengan, Kraton, Kec. Krian, Kab. Sidoarjo, Jawa Timur Telp : 085655863676 Email : atmakarsa.id@gmail.com
F7: Tanggal : | G7: 45757
A11: Telah terima | B11: : | C11: ="1. Faktur Penjualan" &" x1" -> 1. Faktur Penjualan x1
C12: ='Faktur Masa (Print)'!$F$12 -> 2260314
C13: =IFERROR(__xludf.DUMMYFUNCTION("""2. Surat Jalan"" &"" x""&COUNTA(SPLIT('Faktur Masa (Print)'!$A$36,"" ""))"),"2. Surat Jalan x4") -> 2. Surat Jalan x4
C14: ='Faktur Masa (Print)'!$A$36 -> 0426533113 0426523078 0426513006 0426502950
A17: Dari/Untuk | B17: : | C17: ='Faktur Masa (Print)'!$F$4 -> Bpk. Kadir (Maintenance Velg)
A19: Yang menyerahkan, | F19: Penerima,
F33: KWITANSI
A35: Jl. Parengan Kali 19, Parengan, Kraton, Kec. Krian, Kab. Sidoarjo, Jawa Timur Telp : 085655863676 Email : atmakarsa.id@gmail.com
A40: Telah terima dari | C40: : | D40: ='Faktur Masa (Print)'!$F$4 -> Bpk. Kadir (Maintenance Velg)
A41: Uang sejumlah | C41: : | D41: =terbilang('Faktur Masa (Print)'!G$30) -> Satu Juta Delapan Ratus Sepuluh Ribu
A42: Untuk pembayaran | C42: : | D42: ="Faktur Nomor "& 'Faktur Masa (Print)'!$F$12 -> Faktur Nomor 2260314
F45: ='Faktur Masa (Print)'!F32 -> Sidoarjo, 17 April 2026
A49: ='Faktur Masa (Print)'!G$30 -> 1810000
F50: ='Faktur Masa (Print)'!F37 -> Wahyono

Sheet database
A1: =IFERROR(__xludf.DUMMYFUNCTION("IMPORTRANGE(""https://docs.google.com/spreadsheets/d/1HW-yrSCd5GRX8NERW7XSFs49YsIB5WzHtomULUEkO2w/edit?usp=sharing"",""inventoryLog!A:O"")"),"inventoryId") -> inventoryId | B1: =IFERROR(__xludf.DUMMYFUNCTION("""COMPUTED_VALUE"""),"docNumber") -> docNumber | C1: =IFERROR(__xludf.DUMMYFUNCTION("""COMPUTED_VALUE"""),"datetime") -> datetime | D1: =IFERROR(__xludf.DUMMYFUNCTION("""COMPUTED_VALUE"""),"customerId") -> customerId | E1: =IFERROR(__xludf.DUMMYFUNCTION("""COMPUTED_VALUE"""),"customerName") -> customerName | F1: =IFERROR(__xludf.DUMMYFUNCTION("""COMPUTED_VALUE"""),"itemId") -> itemId | G1: =IFERROR(__xludf.DUMMYFUNCTION("""COMPUTED_VALUE"""),"itemName") -> itemName | H1: =IFERROR(__xludf.DUMMYFUNCTION("""COMPUTED_VALUE"""),"mutation") -> mutation | I1: =IFERROR(__xludf.DUMMYFUNCTION("""COMPUTED_VALUE"""),"mutationCode") -> mutationCode | J1: =IFERROR(__xludf.DUMMYFUNCTION("""COMPUTED_VALUE"""),"qty") -> qty | K1: =IFERROR(__xludf.DUMMYFUNCTION("""COMPUTED_VALUE"""),"itemNumber") -> itemNumber | L1: =IFERROR(__xludf.DUMMYFUNCTION("""COMPUTED_VALUE"""),"price") -> price | M1: =IFERROR(__xludf.DUMMYFUNCTION("""COMPUTED_VALUE"""),"description") -> description | N1: =IFERROR(__xludf.DUMMYFUNCTION("""COMPUTED_VALUE"""),"adminNote") -> adminNote | O1: =IFERROR(__xludf.DUMMYFUNCTION("""COMPUTED_VALUE"""),"isCorrection") -> isCorrection | Q1: =IFERROR(__xludf.DUMMYFUNCTION("IMPORTRANGE(""https://docs.google.com/spreadsheets/d/1HW-yrSCd5GRX8NERW7XSFs49YsIB5WzHtomULUEkO2w/edit?usp=sharing"",""documentLog!A:h"")"),"inventoryId") -> inventoryId | R1: =IFERROR(__xludf.DUMMYFUNCTION("""COMPUTED_VALUE"""),"docNumber") -> docNumber | S1: =IFERROR(__xludf.DUMMYFUNCTION("""COMPUTED_VALUE"""),"customerId") -> customerId | T1: =IFERROR(__xludf.DUMMYFUNCTION("""COMPUTED_VALUE"""),"customerName") -> customerName | U1: =IFERROR(__xludf.DUMMYFUNCTION("""COMPUTED_VALUE"""),"datetime") -> datetime | V1: =IFERROR(__xludf.DUMMYFUNCTION("""COMPUTED_VALUE"""),"address") -> address | W1: =IFERROR(__xludf.DUMMYFUNCTION("""COMPUTED_VALUE"""),"mutation") -> mutation | X1: =IFERROR(__xludf.DUMMYFUNCTION("""COMPUTED_VALUE"""),"customerSign") -> customerSign | Z1: docNumDescNormal | AA1: docNumDescOther | AC1: =IFERROR(__xludf.DUMMYFUNCTION("IMPORTRANGE(""https://docs.google.com/spreadsheets/d/1HW-yrSCd5GRX8NERW7XSFs49YsIB5WzHtomULUEkO2w/edit?usp=sharing"",""customerDetails!A:h"")"),"customerId") -> customerId | AD1: =IFERROR(__xludf.DUMMYFUNCTION("""COMPUTED_VALUE"""),"customerName") -> customerName | AE1: =IFERROR(__xludf.DUMMYFUNCTION("""COMPUTED_VALUE"""),"npwp") -> npwp | AF1: =IFERROR(__xludf.DUMMYFUNCTION("""COMPUTED_VALUE"""),"ppn") -> ppn | AG1: =IFERROR(__xludf.DUMMYFUNCTION("""COMPUTED_VALUE"""),"address") -> address | AH1: =IFERROR(__xludf.DUMMYFUNCTION("""COMPUTED_VALUE"""),"termin") -> termin | AI1: =IFERROR(__xludf.DUMMYFUNCTION("""COMPUTED_VALUE"""),"call") -> call | AJ1: =IFERROR(__xludf.DUMMYFUNCTION("""COMPUTED_VALUE"""),"reportUpdates") -> reportUpdates | AL1: =IFERROR(__xludf.DUMMYFUNCTION("QUERY(IMPORTRANGE(""https://docs.google.com/spreadsheets/d/1HW-yrSCd5GRX8NERW7XSFs49YsIB5WzHtomULUEkO2w/edit?usp=sharing"",""customInv!A:G""),""SELECT * ORDER BY Col5 DESC"",1)"),"concatDocNumber") -> concatDocNumber | AM1: =IFERROR(__xludf.DUMMYFUNCTION("""COMPUTED_VALUE"""),"docNumber") -> docNumber | AN1: =IFERROR(__xludf.DUMMYFUNCTION("""COMPUTED_VALUE"""),"customerId") -> customerId | AO1: =IFERROR(__xludf.DUMMYFUNCTION("""COMPUTED_VALUE"""),"customerName") -> customerName | AP1: =IFERROR(__xludf.DUMMYFUNCTION("""COMPUTED_VALUE"""),"datetime") -> datetime | AQ1: =IFERROR(__xludf.DUMMYFUNCTION("""COMPUTED_VALUE"""),"docDate") -> docDate | AR1: =IFERROR(__xludf.DUMMYFUNCTION("""COMPUTED_VALUE"""),"") | AS1: =IFERROR(__xludf.DUMMYFUNCTION("IMPORTRANGE(""https://docs.google.com/spreadsheets/d/1HW-yrSCd5GRX8NERW7XSFs49YsIB5WzHtomULUEkO2w/edit?usp=sharing"",""customerDetails!A:h"")"),"customerId") -> customerId | AT1: =IFERROR(__xludf.DUMMYFUNCTION("""COMPUTED_VALUE"""),"customerName") -> customerName | AU1: =IFERROR(__xludf.DUMMYFUNCTION("""COMPUTED_VALUE"""),"npwp") -> npwp | AV1: =IFERROR(__xludf.DUMMYFUNCTION("""COMPUTED_VALUE"""),"ppn") -> ppn | AW1: =IFERROR(__xludf.DUMMYFUNCTION("""COMPUTED_VALUE"""),"address") -> address | AX1: =IFERROR(__xludf.DUMMYFUNCTION("""COMPUTED_VALUE"""),"termin") -> termin | AY1: =IFERROR(__xludf.DUMMYFUNCTION("""COMPUTED_VALUE"""),"call") -> call | AZ1: =IFERROR(__xludf.DUMMYFUNCTION("""COMPUTED_VALUE"""),"reportUpdates") -> reportUpdates | BB1: =IFERROR(__xludf.DUMMYFUNCTION("IMPORTRANGE(""https://docs.google.com/spreadsheets/d/1HW-yrSCd5GRX8NERW7XSFs49YsIB5WzHtomULUEkO2w/edit?usp=sharing"",""itemCategoryDetails!A:H"")"),"itemId") -> itemId | BC1: =IFERROR(__xludf.DUMMYFUNCTION("""COMPUTED_VALUE"""),"itemName") -> itemName | BD1: =IFERROR(__xludf.DUMMYFUNCTION("""COMPUTED_VALUE"""),"category") -> category | BE1: =IFERROR(__xludf.DUMMYFUNCTION("""COMPUTED_VALUE"""),"tags") -> tags | BF1: =IFERROR(__xludf.DUMMYFUNCTION("""COMPUTED_VALUE"""),"satuan") -> satuan | BG1: =IFERROR(__xludf.DUMMYFUNCTION("""COMPUTED_VALUE"""),"description") -> description | BH1: =IFERROR(__xludf.DUMMYFUNCTION("""COMPUTED_VALUE"""),"priviledge") -> priviledge
A2: =IFERROR(__xludf.DUMMYFUNCTION("""COMPUTED_VALUE"""),"08240001") -> 08240001 | B2: =IFERROR(__xludf.DUMMYFUNCTION("""COMPUTED_VALUE"""),"08240001") -> 08240001 | C2: =IFERROR(__xludf.DUMMYFUNCTION("""COMPUTED_VALUE"""),45527.40744212963) -> 45527.407 | D2: =IFERROR(__xludf.DUMMYFUNCTION("""COMPUTED_VALUE"""),"a9fe1bea") -> a9fe1bea | E2: =IFERROR(__xludf.DUMMYFUNCTION("""COMPUTED_VALUE"""),"H. Suheiri") -> H. Suheiri | F2: =IFERROR(__xludf.DUMMYFUNCTION("""COMPUTED_VALUE"""),"8bdbe149") -> 8bdbe149 | G2: =IFERROR(__xludf.DUMMYFUNCTION("""COMPUTED_VALUE"""),"Oksigen 6m3") -> Oksigen 6m3 | H2: =IFERROR(__xludf.DUMMYFUNCTION("""COMPUTED_VALUE"""),"OUT") -> OUT | I2: =IFERROR(__xludf.DUMMYFUNCTION("""COMPUTED_VALUE"""),"NORMAL") -> NORMAL | J2: =IFERROR(__xludf.DUMMYFUNCTION("""COMPUTED_VALUE"""),20.0) -> 20 | K2: =IFERROR(__xludf.DUMMYFUNCTION("""COMPUTED_VALUE"""),"1105 1113 1124 1125 1144 1145 1136 1134 1143 1139 1137 1135 1141 1142 1140 1133 1132 1123 1118 1108") -> 1105 1113 1124 1125 1144 1145 1136 1134 1143 1139 1137 1135 1141 1142 1140 1133 1132 1123 1118 1108 | L2: =IFERROR(__xludf.DUMMYFUNCTION("""COMPUTED_VALUE"""),50000.0) -> 50000 | Q2: =IFERROR(__xludf.DUMMYFUNCTION("""COMPUTED_VALUE"""),"08240001") -> 08240001 | R2: =IFERROR(__xludf.DUMMYFUNCTION("""COMPUTED_VALUE"""),"08240001") -> 08240001 | S2: =IFERROR(__xludf.DUMMYFUNCTION("""COMPUTED_VALUE"""),"a9fe1bea") -> a9fe1bea | T2: =IFERROR(__xludf.DUMMYFUNCTION("""COMPUTED_VALUE"""),"H. Suheiri") -> H. Suheiri | U2: =IFERROR(__xludf.DUMMYFUNCTION("""COMPUTED_VALUE"""),45527.407442129625) -> 45527.407 | V2: =IFERROR(__xludf.DUMMYFUNCTION("""COMPUTED_VALUE"""),"Jalan Raya Balongbendo No. 6 RT. 1 / RW. 1 Singkalan, Singkalan, Seduri, Kec. BalongBendo, Kabupaten Sidoarjo, Jawa Timur 61263") -> Jalan Raya Balongbendo No. 6 RT. 1 / RW. 1 Singkalan, Singkalan, Seduri, Kec. BalongBendo, Kabupaten Sidoarjo, Jawa Timur 61263 | W2: =IFERROR(__xludf.DUMMYFUNCTION("""COMPUTED_VALUE"""),"OUT") -> OUT | Z2: =IFERROR(__xludf.DUMMYFUNCTION("QUERY($R$2:$W5004,""SELECT R WHERE W='OUT' ORDER BY U DESC"")"),"04261063117") -> 04261063117 | AA2: =IFERROR(__xludf.DUMMYFUNCTION("QUERY($R$2:$W5004,""SELECT R WHERE W='OTHER' ORDER BY U DESC"")"),"4042612928") -> 4042612928 | AC2: =IFERROR(__xludf.DUMMYFUNCTION("""COMPUTED_VALUE"""),"7b9d8eba") -> 7b9d8eba | AD2: =IFERROR(__xludf.DUMMYFUNCTION("""COMPUTED_VALUE"""),"PT PELANGI INDOKARYA") -> PT PELANGI INDOKARYA | AE2: =IFERROR(__xludf.DUMMYFUNCTION("""COMPUTED_VALUE"""),"025249210606000") -> 025249210606000 | AF2: =IFERROR(__xludf.DUMMYFUNCTION("""COMPUTED_VALUE"""),TRUE) -> TRUE | AG2: =IFERROR(__xludf.DUMMYFUNCTION("""COMPUTED_VALUE"""),"Jl Medokan Semampir Indah Sukokilo No 129 RT. 005 RW. 008 Medokan Semampir Sukokilo Kota Surabaya Jawa Timur 60119") -> Jl Medokan Semampir Indah Sukokilo No 129 RT. 005 RW. 008 Medokan Semampir Sukokilo Kota Surabaya Jawa Timur 60119 | AH2: =IFERROR(__xludf.DUMMYFUNCTION("""COMPUTED_VALUE"""),30.0) -> 30 | AJ2: =IFERROR(__xludf.DUMMYFUNCTION("""COMPUTED_VALUE"""),45887.854166666664) -> 45887.854 | AL2: =IFERROR(__xludf.DUMMYFUNCTION("""COMPUTED_VALUE"""),"2260314") -> 2260314 | AM2: =IFERROR(__xludf.DUMMYFUNCTION("""COMPUTED_VALUE"""),"0426502950") -> 0426502950 | AN2: =IFERROR(__xludf.DUMMYFUNCTION("""COMPUTED_VALUE"""),"ec231cc9") -> ec231cc9 | AO2: =IFERROR(__xludf.DUMMYFUNCTION("""COMPUTED_VALUE"""),"Bpk. Kohir (Maintenance Velg)") -> Bpk. Kohir (Maintenance Velg) | AP2: =IFERROR(__xludf.DUMMYFUNCTION("""COMPUTED_VALUE"""),46129.46581018518) -> 46129.466 | AQ2: =IFERROR(__xludf.DUMMYFUNCTION("""COMPUTED_VALUE"""),46113.0) -> 46113 | AS2: =IFERROR(__xludf.DUMMYFUNCTION("""COMPUTED_VALUE"""),"7b9d8eba") -> 7b9d8eba | AT2: =IFERROR(__xludf.DUMMYFUNCTION("""COMPUTED_VALUE"""),"PT PELANGI INDOKARYA") -> PT PELANGI INDOKARYA | AU2: =IFERROR(__xludf.DUMMYFUNCTION("""COMPUTED_VALUE"""),"025249210606000") -> 025249210606000 | AV2: =IFERROR(__xludf.DUMMYFUNCTION("""COMPUTED_VALUE"""),TRUE) -> TRUE | AW2: =IFERROR(__xludf.DUMMYFUNCTION("""COMPUTED_VALUE"""),"Jl Medokan Semampir Indah Sukokilo No 129 RT. 005 RW. 008 Medokan Semampir Sukokilo Kota Surabaya Jawa Timur 60119") -> Jl Medokan Semampir Indah Sukokilo No 129 RT. 005 RW. 008 Medokan Semampir Sukokilo Kota Surabaya Jawa Timur 60119 | AX2: =IFERROR(__xludf.DUMMYFUNCTION("""COMPUTED_VALUE"""),30.0) -> 30 | AZ2: =IFERROR(__xludf.DUMMYFUNCTION("""COMPUTED_VALUE"""),45887.854166666664) -> 45887.854 | BB2: =IFERROR(__xludf.DUMMYFUNCTION("""COMPUTED_VALUE"""),"3b9d6a30") -> 3b9d6a30 | BC2: =IFERROR(__xludf.DUMMYFUNCTION("""COMPUTED_VALUE"""),"Acetyline") -> Acetyline | BD2: =IFERROR(__xludf.DUMMYFUNCTION("""COMPUTED_VALUE"""),"RENT") -> RENT | BE2: =IFERROR(__xludf.DUMMYFUNCTION("""COMPUTED_VALUE"""),"MP") -> MP | BF2: =IFERROR(__xludf.DUMMYFUNCTION("""COMPUTED_VALUE"""),"Btl") -> Btl | BH2: =IFERROR(__xludf.DUMMYFUNCTION("""COMPUTED_VALUE"""),TRUE) -> TRUE
A3: =IFERROR(__xludf.DUMMYFUNCTION("""COMPUTED_VALUE"""),"08240002") -> 08240002 | B3: =IFERROR(__xludf.DUMMYFUNCTION("""COMPUTED_VALUE"""),"08240002") -> 08240002 | C3: =IFERROR(__xludf.DUMMYFUNCTION("""COMPUTED_VALUE"""),45527.43210648148) -> 45527.432 | D3: =IFERROR(__xludf.DUMMYFUNCTION("""COMPUTED_VALUE"""),"e968afef") -> e968afef | E3: =IFERROR(__xludf.DUMMYFUNCTION("""COMPUTED_VALUE"""),"Bpk. Agus") -> Bpk. Agus | F3: =IFERROR(__xludf.DUMMYFUNCTION("""COMPUTED_VALUE"""),"8bdbe149") -> 8bdbe149 | G3: =IFERROR(__xludf.DUMMYFUNCTION("""COMPUTED_VALUE"""),"Oksigen 6m3") -> Oksigen 6m3 | H3: =IFERROR(__xludf.DUMMYFUNCTION("""COMPUTED_VALUE"""),"OUT") -> OUT | I3: =IFERROR(__xludf.DUMMYFUNCTION("""COMPUTED_VALUE"""),"NORMAL") -> NORMAL | J3: =IFERROR(__xludf.DUMMYFUNCTION("""COMPUTED_VALUE"""),10.0) -> 10 | K3: =IFERROR(__xludf.DUMMYFUNCTION("""COMPUTED_VALUE"""),"1109 1102 1114 1111 1115 1110 1107 1106 1103 1104") -> 1109 1102 1114 1111 1115 1110 1107 1106 1103 1104 | L3: =IFERROR(__xludf.DUMMYFUNCTION("""COMPUTED_VALUE"""),60000.0) -> 60000 | Q3: =IFERROR(__xludf.DUMMYFUNCTION("""COMPUTED_VALUE"""),"08240002") -> 08240002 | R3: =IFERROR(__xludf.DUMMYFUNCTION("""COMPUTED_VALUE"""),"08240002") -> 08240002 | S3: =IFERROR(__xludf.DUMMYFUNCTION("""COMPUTED_VALUE"""),"e968afef") -> e968afef | T3: =IFERROR(__xludf.DUMMYFUNCTION("""COMPUTED_VALUE"""),"Bpk. Agus") -> Bpk. Agus | U3: =IFERROR(__xludf.DUMMYFUNCTION("""COMPUTED_VALUE"""),45527.43210648149) -> 45527.432 | V3: =IFERROR(__xludf.DUMMYFUNCTION("""COMPUTED_VALUE"""),"Jl. Parengan 13, Semawut, Balongbendo, Kec. BalongBendo, Kabupaten Sidoarjo, Jawa Timur 61263") -> Jl. Parengan 13, Semawut, Balongbendo, Kec. BalongBendo, Kabupaten Sidoarjo, Jawa Timur 61263 | W3: =IFERROR(__xludf.DUMMYFUNCTION("""COMPUTED_VALUE"""),"OUT") -> OUT | Z3: =IFERROR(__xludf.DUMMYFUNCTION("""COMPUTED_VALUE"""),"0426533113") -> 0426533113 | AA3: =IFERROR(__xludf.DUMMYFUNCTION("""COMPUTED_VALUE"""),"4032632926") -> 4032632926 | AC3: =IFERROR(__xludf.DUMMYFUNCTION("""COMPUTED_VALUE"""),"f8335a53") -> f8335a53 | AD3: =IFERROR(__xludf.DUMMYFUNCTION("""COMPUTED_VALUE"""),"CV RAGAM JAYA ENGINEERING") -> CV RAGAM JAYA ENGINEERING | AF3: =IFERROR(__xludf.DUMMYFUNCTION("""COMPUTED_VALUE"""),TRUE) -> TRUE | AG3: =IFERROR(__xludf.DUMMYFUNCTION("""COMPUTED_VALUE"""),"Jl. Balung wangon, Dadapkuning, Bulurejo, Kec. Benjeng, Kabupaten Gresik, Jawa Timur 61172") -> Jl. Balung wangon, Dadapkuning, Bulurejo, Kec. Benjeng, Kabupaten Gresik, Jawa Timur 61172 | AH3: =IFERROR(__xludf.DUMMYFUNCTION("""COMPUTED_VALUE"""),30.0) -> 30 | AL3: =IFERROR(__xludf.DUMMYFUNCTION("""COMPUTED_VALUE"""),"2260314") -> 2260314 | AM3: =IFERROR(__xludf.DUMMYFUNCTION("""COMPUTED_VALUE"""),"0426513006") -> 0426513006 | AN3: =IFERROR(__xludf.DUMMYFUNCTION("""COMPUTED_VALUE"""),"ec231cc9") -> ec231cc9 | AO3: =IFERROR(__xludf.DUMMYFUNCTION("""COMPUTED_VALUE"""),"Bpk. Kohir (Maintenance Velg)") -> Bpk. Kohir (Maintenance Velg) | AP3: =IFERROR(__xludf.DUMMYFUNCTION("""COMPUTED_VALUE"""),46129.46581018518) -> 46129.466 | AQ3: =IFERROR(__xludf.DUMMYFUNCTION("""COMPUTED_VALUE"""),46119.0) -> 46119 | AS3: =IFERROR(__xludf.DUMMYFUNCTION("""COMPUTED_VALUE"""),"f8335a53") -> f8335a53 | AT3: =IFERROR(__xludf.DUMMYFUNCTION("""COMPUTED_VALUE"""),"CV RAGAM JAYA ENGINEERING") -> CV RAGAM JAYA ENGINEERING | AV3: =IFERROR(__xludf.DUMMYFUNCTION("""COMPUTED_VALUE"""),TRUE) -> TRUE | AW3: =IFERROR(__xludf.DUMMYFUNCTION("""COMPUTED_VALUE"""),"Jl. Balung wangon, Dadapkuning, Bulurejo, Kec. Benjeng, Kabupaten Gresik, Jawa Timur 61172") -> Jl. Balung wangon, Dadapkuning, Bulurejo, Kec. Benjeng, Kabupaten Gresik, Jawa Timur 61172 | AX3: =IFERROR(__xludf.DUMMYFUNCTION("""COMPUTED_VALUE"""),30.0) -> 30 | BB3: =IFERROR(__xludf.DUMMYFUNCTION("""COMPUTED_VALUE"""),"66af7c72") -> 66af7c72 | BC3: =IFERROR(__xludf.DUMMYFUNCTION("""COMPUTED_VALUE"""),"Argon 6m3") -> Argon 6m3 | BD3: =IFERROR(__xludf.DUMMYFUNCTION("""COMPUTED_VALUE"""),"RENT") -> RENT | BE3: =IFERROR(__xludf.DUMMYFUNCTION("""COMPUTED_VALUE"""),"MP") -> MP | BF3: =IFERROR(__xludf.DUMMYFUNCTION("""COMPUTED_VALUE"""),"Btl") -> Btl | BH3: =IFERROR(__xludf.DUMMYFUNCTION("""COMPUTED_VALUE"""),TRUE) -> TRUE
A4: =IFERROR(__xludf.DUMMYFUNCTION("""COMPUTED_VALUE"""),"75bc467e") -> 75bc467e | B4: =IFERROR(__xludf.DUMMYFUNCTION("""COMPUTED_VALUE"""),"75bc467e") -> 75bc467e | C4: =IFERROR(__xludf.DUMMYFUNCTION("""COMPUTED_VALUE"""),45530.43541666667) -> 45530.435 | D4: =IFERROR(__xludf.DUMMYFUNCTION("""COMPUTED_VALUE"""),"a9fe1bea") -> a9fe1bea | E4: =IFERROR(__xludf.DUMMYFUNCTION("""COMPUTED_VALUE"""),"H. Suheiri") -> H. Suheiri | F4: =IFERROR(__xludf.DUMMYFUNCTION("""COMPUTED_VALUE"""),"8bdbe149") -> 8bdbe149 | G4: =IFERROR(__xludf.DUMMYFUNCTION("""COMPUTED_VALUE"""),"Oksigen 6m3") -> Oksigen 6m3 | H4: =IFERROR(__xludf.DUMMYFUNCTION("""COMPUTED_VALUE"""),"IN") -> IN | I4: =IFERROR(__xludf.DUMMYFUNCTION("""COMPUTED_VALUE"""),"EMPTY") -> EMPTY | J4: =IFERROR(__xludf.DUMMYFUNCTION("""COMPUTED_VALUE"""),4.0) -> 4 | K4: =IFERROR(__xludf.DUMMYFUNCTION("""COMPUTED_VALUE"""),"1139 1113 1105 1135") -> 1139 1113 1105 1135 | Q4: =IFERROR(__xludf.DUMMYFUNCTION("""COMPUTED_VALUE"""),"75bc467e") -> 75bc467e | R4: =IFERROR(__xludf.DUMMYFUNCTION("""COMPUTED_VALUE"""),"75bc467e") -> 75bc467e | S4: =IFERROR(__xludf.DUMMYFUNCTION("""COMPUTED_VALUE"""),"a9fe1bea") -> a9fe1bea | T4: =IFERROR(__xludf.DUMMYFUNCTION("""COMPUTED_VALUE"""),"H. Suheiri") -> H. Suheiri | U4: =IFERROR(__xludf.DUMMYFUNCTION("""COMPUTED_VALUE"""),45530.43541666667) -> 45530.435 | V4: =IFERROR(__xludf.DUMMYFUNCTION("""COMPUTED_VALUE"""),"Jalan Raya Balongbendo No. 6 RT. 1 / RW. 1 Singkalan, Singkalan, Seduri, Kec. BalongBendo, Kabupaten Sidoarjo, Jawa Timur 61263") -> Jalan Raya Balongbendo No. 6 RT. 1 / RW. 1 Singkalan, Singkalan, Seduri, Kec. BalongBendo, Kabupaten Sidoarjo, Jawa Timur 61263 | W4: =IFERROR(__xludf.DUMMYFUNCTION("""COMPUTED_VALUE"""),"IN") -> IN | Z4: =IFERROR(__xludf.DUMMYFUNCTION("""COMPUTED_VALUE"""),"04261053112") -> 04261053112 | AA4: =IFERROR(__xludf.DUMMYFUNCTION("""COMPUTED_VALUE"""),"4032622925") -> 4032622925 | AC4: =IFERROR(__xludf.DUMMYFUNCTION("""COMPUTED_VALUE"""),"e86baf3b") -> e86baf3b | AD4: =IFERROR(__xludf.DUMMYFUNCTION("""COMPUTED_VALUE"""),"PT GEMILANG CIPTA WAWASAN") -> PT GEMILANG CIPTA WAWASAN | AE4: =IFERROR(__xludf.DUMMYFUNCTION("""COMPUTED_VALUE"""),"019634344015000") -> 019634344015000 | AF4: =IFERROR(__xludf.DUMMYFUNCTION("""COMPUTED_VALUE"""),TRUE) -> TRUE | AG4: =IFERROR(__xludf.DUMMYFUNCTION("""COMPUTED_VALUE"""),"JL TEBET RAYA, 2A, TEBET BARAT, TEBET, KOTA ADM, JAKARTA SELATAN, DKI JAKARTA") -> JL TEBET RAYA, 2A, TEBET BARAT, TEBET, KOTA ADM, JAKARTA SELATAN, DKI JAKARTA | AH4: =IFERROR(__xludf.DUMMYFUNCTION("""COMPUTED_VALUE"""),30.0) -> 30 | AJ4: =IFERROR(__xludf.DUMMYFUNCTION("""COMPUTED_VALUE"""),46081.60934027778) -> 46081.609 | AL4: =IFERROR(__xludf.DUMMYFUNCTION("""COMPUTED_VALUE"""),"2260314") -> 2260314 | AM4: =IFERROR(__xludf.DUMMYFUNCTION("""COMPUTED_VALUE"""),"0426523078") -> 0426523078 | AN4: =IFERROR(__xludf.DUMMYFUNCTION("""COMPUTED_VALUE"""),"ec231cc9") -> ec231cc9 | AO4: =IFERROR(__xludf.DUMMYFUNCTION("""COMPUTED_VALUE"""),"Bpk. Kohir (Maintenance Velg)") -> Bpk. Kohir (Maintenance Velg) | AP4: =IFERROR(__xludf.DUMMYFUNCTION("""COMPUTED_VALUE"""),46129.46581018518) -> 46129.466 | AQ4: =IFERROR(__xludf.DUMMYFUNCTION("""COMPUTED_VALUE"""),46126.0) -> 46126 | AS4: =IFERROR(__xludf.DUMMYFUNCTION("""COMPUTED_VALUE"""),"e86baf3b") -> e86baf3b | AT4: =IFERROR(__xludf.DUMMYFUNCTION("""COMPUTED_VALUE"""),"PT GEMILANG CIPTA WAWASAN") -> PT GEMILANG CIPTA WAWASAN | AU4: =IFERROR(__xludf.DUMMYFUNCTION("""COMPUTED_VALUE"""),"019634344015000") -> 019634344015000 | AV4: =IFERROR(__xludf.DUMMYFUNCTION("""COMPUTED_VALUE"""),TRUE) -> TRUE | AW4: =IFERROR(__xludf.DUMMYFUNCTION("""COMPUTED_VALUE"""),"JL TEBET RAYA, 2A, TEBET BARAT, TEBET, KOTA ADM, JAKARTA SELATAN, DKI JAKARTA") -> JL TEBET RAYA, 2A, TEBET BARAT, TEBET, KOTA ADM, JAKARTA SELATAN, DKI JAKARTA | AX4: =IFERROR(__xludf.DUMMYFUNCTION("""COMPUTED_VALUE"""),30.0) -> 30 | AZ4: =IFERROR(__xludf.DUMMYFUNCTION("""COMPUTED_VALUE"""),46081.60934027778) -> 46081.609 | BB4: =IFERROR(__xludf.DUMMYFUNCTION("""COMPUTED_VALUE"""),"ce3b37d3") -> ce3b37d3 | BC4: =IFERROR(__xludf.DUMMYFUNCTION("""COMPUTED_VALUE"""),"Argon MR") -> Argon MR | BD4: =IFERROR(__xludf.DUMMYFUNCTION("""COMPUTED_VALUE"""),"RENT") -> RENT | BE4: =IFERROR(__xludf.DUMMYFUNCTION("""COMPUTED_VALUE"""),"MR") -> MR | BF4: =IFERROR(__xludf.DUMMYFUNCTION("""COMPUTED_VALUE"""),"Btl") -> Btl | BH4: =IFERROR(__xludf.DUMMYFUNCTION("""COMPUTED_VALUE"""),FALSE) -> FALSE
